Workbook

Sheet MEMORIA
A1: MEMÓRIA DE CALCULO PDDE BÁSICO
A2: CEC DO/A
A3: CNPJ:
A4: Endereço:
A6: Agência | C6: Conta corrente:
A7: Bloco 1- Redimentos
A8: Mês | B8: Fundo 1 | C8: Fundo 2
A9: janeiro
A10: fevereiro
A11: março
A12: abril
A13: maio
A14: junho
A15: julho
A16: agosto
A17: setembro
A18: outubro
A19: novembro
A20: dezembro
A21: Subtotal | B21: =SUM(B9:B20) -> 0 | C21: =SUM(C9:C20) -> 0
A22: total | B22: =B21+C21 -> 0
A24: Bloco 2- Despesas
A26: PDDE BÁSICO
A27: CUSTEIO | E27: CAPITAL
A28: Saldo anterior | E28: Saldo anterior
A29: recebido no exercício 1ª PARCELA | E29: recebido no exercício 1ª PARCELA
A30: recebido no exercício 2ª PARCELA | E30: recebido no exercício 2ª PARCELA
A31: Total recebido | C31: =C29+C30 -> 0 | E31: Total recebido | G31: =G29+G30 -> 0
A32: Rendimentos | C32: 0 | E32: Rendimentos | G32: 0
A33: Recursos Próprios | C33: 0 | E33: Recursos Próprios | G33: 0
A34: DEVOLVIDO AO FNDE | C34: 0 | E34: DEVOLVIDO AO FNDE | G34: 0
A35: Despesa | C35: =Demonstrativo!D25 -> 0 | E35: Despesa | G35: =Demonstrativo!F25 -> 0
A36: SALDO DEVOLVIDO | C36: 0 | E36: SALDO DEVOLVIDO | G36: 0
A37: Saldo a reprogramar | C37: =C28+C29+C30+C32+C33-C35-C36 -> 0 | E37: Saldo a reprogramar | G37: =G28+G29+G30+G32+G33-G35-G36 -> 0
A40: Bloco 3- Conferência com extrato
A42: Saldo inicial dos programas | E42: Saldo final dos programas
A43: saldo inicial | C43: =C28+G28 -> 0 | E43: final | G43: =C37+G37 -> 0
A44: Saldo extrato de C/C | C44: 0 | E44: Saldo extrato de C/C
A45: Saldo final rendimento 1 | C45: 0 | E45: Saldo final rendimento 1
A46: Saldo final rendimento 2 | C46: 0 | E46: Saldo final rendimento 2
...

Sheet Demonstrativo
A4: FUNDO NACIONAL DE DESESNVOLVIMENTO DA EDUCAÇÃO
A5: DIRETORIA FINANCEIRA COORDENAÇÃO-GERAL DE CONTABILIDADE E ACOMPANHAMENTO DE PRESTAÇÃO DE CONTAS
A9: BLOCO 1 - IDENTIFICAÇÃO
A10: 01- Programa/ Ação | Q10: 02- exercíciio
A11: FNDE/PDDE/BÁSICO | Q11: 2026
A13: 03- Nome da Razão social | O13: 04- CNPJ
A14: CEC DO/A | C14: =MEMORIA!B2 -> EDI CÔNEGO FERNANDES PINHEIRO | O14: =MEMORIA!B3 -> 1294812000150
A15: 05 - Endereço | O15: 06- Municipio | Q15: 07 - UF
A16: =MEMORIA!B4 -> RUA SEBASTIAN BACH S/Nº , JARDIM AMÉRICA - CEP: 21240370 | O16: Rio de Janeiro | Q16: RJ
A19: BLOCO 2 - SÍNTESE DA EXECUÇÃO DA RECEITA E DA DESPESA (R$)
A20: 08 - Saldo do Exerc. Anterior | D20: 09 - Valor Recebido no Exercício | H20: 10 - Recursos Próprios | N20: 11- Rend. de Aplicação Financeira | P20: 12- Devolução ao FNDE (-)
A21: Custeio | C21: Capital | D21: Custeio | F21: Capital | H21: Custeio | K21: Capital | N21: Custeio | O21: Capital | P21: Custeio | Q21: Capital
A22: =MEMORIA!C28 -> 0 | C22: =MEMORIA!G28 -> 0 | D22: =MEMORIA!C31 -> 0 | F22: =MEMORIA!G31 -> 0 | H22: =MEMORIA!C33 -> 0 | K22: =MEMORIA!G33 -> 0 | N22: =MEMORIA!C32 -> 0 | O22: =MEMORIA!G32 -> 0 | P22: =MEMORIA!C34 -> 0 | Q22: =MEMORIA!G34 -> 0
A23: 13 - Valor Total da Receita | D23: 14- Despesa realizada | H23: 15- Saldo a Reprogramar Exerc. Seguinte | M23: 16 - Saldo Devolvido | O23: 17- Período de Execução | Q23: 18- Nº de Escolas
A24: Custeio | C24: Capital | D24: Custeio | F24: Capital | H24: Custeio | K24: Capital | M24: Custeio | N24: Capital | O24: 01/01/2026 A 31/12/2026 | Q24: 1
A25: =A22+D22+H22+N22-P22 -> 0 | C25: =C22+F22+K22+O22-Q22 -> 0 | D25: =SUMIF(K30:K151,"=CUSTEIO",Q30:Q151) -> 0 | F25: =SUMIF(K30:K151,"=CAPITAL",Q30:Q151) -> 0 | H25: =SUM(A25-D25-M25) -> 0 | K25: =SUM(C25-F25-N25) -> 0 | M25: =MEMORIA!C36 -> 0 | N25: =MEMORIA!G36 -> 0
A27: BLOCO 3 - PAGAMENTOS EFETUADOS
A28: 19 - Item | B28: 20 - Nome do Favorecido e CNPJ ou CPF | E28: 21 - Tipo de Bens e Materiais Adquiridos | I28: 22 - Orig. R$(*) | K28: 23- Nat. Desp. | L28: 24 - Documento | O28: 25 - Pagamento | Q28: 26- valor (R$)
E29: ou Serviços Contratados( indicar também a atividade) | L29: Tipo | M29: Número | N29: Data | O29: Nº Ch/OB | P29: Data
A30: 1 | I30: FNDE | K30: CUSTEIO
A32: 2 | I32: FNDE
A34: 3 | I34: FNDE
A36: 4 | I36: FNDE
A38: 5 | I38: FNDE
A40: 6 | I40: FNDE
A42: 7 | I42: FNDE
A44: 8 | I44: FNDE
A46: 27 - TOTAL | E46: =IF(Q67>0.1,"À tranportar","Total") -> Total | P46: =SUM(Q30:Q45) -> 0
A49: BLOCO 4 - AUTENTICAÇÃO
A51: Rio de Janeiro, 31 de dezembro de 2026. | H51: =MEMORIA!A52 -> ODETTE DOS SANTOS SACRAMENTO TERREZO FARDILHA
B52: Local e Data | H52: Nome do(a) Dirigente ou Representante Legal | O52: Assinatura do(a) Dirigente ou do Representante Legal
A57: DIRETORIA FINANCEIRA COORDENAÇÃO-GERAL DE CONTABILIDADE E ACOMPANHAMENTO DE PRESTAÇÃO DE CONTAS
A62: BLOCO 3 - PAGAMENTOS EFETUADOS (CONTINUAÇÃO)
A63: 19 - Item | B63: 20 - Nome do Favorecido e CNPJ ou CPF | E63: 21 - Tipo de Bens e Materiais Adquiridos | I63: 22 - Orig. R$(*) | K63: 23- Nat. Desp. | L63: 24 - Documento | O63: 25 - Pagamento
E64: ou Serviços Contratados(indicar também atividades) | L64: Tipo | M64: Número | N64: Data | O64: Nº Ch/OB | P64: Data
O65: Transporte
Q66: =P46 -> 0
A67: 9 | I67: FNDE
A69: 10 | I69: FNDE
A71: 11 | I71: FNDE
...

Sheet Conciliação Bancária
A2: FUNDO NACIONAL DE DESESNVOLVIMENTO DA EDUCAÇÃO DIRETORIA FINANCEIRA COORDENAÇÃO-GERAL DE CONTABILIDADE E ACOMPANHAMENTO DE PRESTAÇÃO DE CONTAS PRESTAÇÃO DE CONTAS
A3: CONCILIAÇÃO BANCÁRIA
A4: BLOCO 1 - IDENTIFICAÇÃO
A5: 01- Programa/ Ação | G5: 02- Exercício
A6: FNDE/PDDE BÁSICO | G6: 2026
A7: 03- Nome da Razão social | G7: 04- CNPJ
A8: =MEMORIA!A2 -> CEC DO/A | B8: =MEMORIA!B2 -> EDI CÔNEGO FERNANDES PINHEIRO | G8: =MEMORIA!B3 -> 1294812000150
A9: 05 - Endereço | F9: 06- Município Rio de Janeiro | H9: 07-UF RJ
A10: =Demonstrativo!A16 -> RUA SEBASTIAN BACH S/Nº , JARDIM AMÉRICA - CEP: 21240370
A12: BLOCO 2- IDENTIFICAÇÃO BANCÁRIA E SALDO
A13: 08- Banco | B13: 09-Cód. da Agência | C13: 10- Nº da Conta Corrente | F13: 11- Saldo do Extrato Bancário
A14: 1 | B14: =MEMORIA!B6 -> 497 | C14: =MEMORIA!F6 -> 415367 | F14: Data: 31/12/2026 | G14: Valor (R$)
G15: =MEMORIA!G47 -> 0
A16: BLOCO 3- DEMONSTRAÇÃO CONTÁBIL/FINANCEIRA
A18: 12- Créditos não Demonstrados no Extrato | D18: 13- Débitos não Demonstrados no Extrato | F18: 14- Restos a Pagar Processados | H18: 15- Saldo contábil (11+12)-(13+14)
A19: Histórico | C19: Valor ($) | D19: Histórico | E19: Valor ($) | F19: Histórico | G19: Valor ($)
H20: =(G15+C20)-(E20-G20) -> 0
A30: 16- TOTAL | H30: =H20 -> 0
A32: BLOCO 4- AUTENTICAÇÃO
A33: RJ, 31/12/26 | C33: =MEMORIA!A52 -> ODETTE DOS SANTOS SACRAMENTO TERREZO FARDILHA
A34: Local e Data | C34: Nome do(a) Dirigente ou Representante Legal | F34: Assinatura do(a) Dirigente ou do Representante Legal
